Workbook

Sheet 01_Executive_Summary
A1: J.B. CHEMICALS & PHARMACEUTICALS LIMITED (NSE: JBCHEPHARM)
B4: Line Item | C4: Value (₹ Cr)
B5: DEAL SUMMARY & RETURN METRICS
B6: KKR Entry Equity Valuation (2020) | C6: 5788
B7: Torrent Exit Equity Valuation (2025) | C7: 25689
B8: Multiple on Invested Capital (MoIC) | C8: ='05_LBO_Returns'!C37 -> 5.9300781
B9: Gross Internal Rate of Return (IRR) | C9: 0.485
B11: Valuation Benchmark | C11: Implied Share Price | D11: Implied Equity Value (₹ Cr)
B12: VALUATION BENCHMARK SUMMARY
B13: 2020 Standalone Intrinsic DCF | C13: 320 | D13: 4972
B14: 2020 KKR Buyout Entry Price | C14: 372.5 | D14: 5788
B15: 2025 Standalone Intrinsic DCF (Base) | C15: ='04_DCF_Valuation'!E30 -> 852.60236 | D15: ='04_DCF_Valuation'!C37 -> 13249.441
B16: 2025 Torrent Strategic M&A Exit | C16: 1600 | D16: 25689
B18: KEY INVESTMENT THESIS & VALUE CREATION PILLARS | C18: Strategic Focus & Financial Execution
B19: Pillar 1: Domestic Formulations Scale | C19: Expanding market share in chronic therapies (Cardiac/Gastro); leveraging market-leading brands CID, Metrogyl, Rantac & Nicardia.
B20: Pillar 2: High-Margin CDMO & Lozenges | C20: Global CDMO partnerships with tier-1 pharma; specialized lozenges manufacturing platform exporting across 40+ countries.
B21: Pillar 3: Operating Leverage & Cash Flow | C21: Expanded EBITDA margins from 21.3% to 26.7%; strong CFO generation paying down debt and supporting 35% dividend payout policy.

Sheet 02_3_Statement_Model
A1: J.B. CHEMICALS & PHARMACEUTICALS LIMITED (NSE: JBCHEPHARM)
A2: Consolidated Financial Statements (Figures in ₹ Crores, unless stated)
B4: INCOME STATEMENT
B6: Line Item | C6: FY20 | D6: FY21 | E6: FY22 | F6: FY23 | G6: FY24 | H6: FY25 | I6: FY26E | J6: FY27E | K6: FY28E | L6: FY29E | M6: FY30E
B7: Revenue from Operations | C7: 1775 | D7: 2043 | E7: 2424 | F7: 3149 | G7: 3484 | H7: 3918 | I7: =I8+I9+I10 -> 4313.025 | J7: =J8+J9+J10 -> 4748.3629 | K7: =K8+K9+K10 -> 5228.1728 | L7: =L8+L9+L10 -> 5730.9063 | M7: =M8+M9+M10 -> 6262.3432
B8: Domestic Formulations | C8: 782 | D8: 893 | E8: 1120 | F8: 1640 | G8: 1902 | H8: 2145 | I8: ='03_Schedules'!D5 -> 2380.95 | J8: ='03_Schedules'!E5 -> 2642.8545 | K8: ='03_Schedules'!F5 -> 2933.5685 | L8: ='03_Schedules'!G5 -> 3241.5932 | M8: ='03_Schedules'!H5 -> 3565.7525
B9: International Formulations | C9: 728 | D9: 845 | E9: 948 | F9: 1050 | G9: 1105 | H9: 1215 | I9: ='03_Schedules'!D7 -> 1318.275 | J9: ='03_Schedules'!E7 -> 1430.3284 | K9: ='03_Schedules'!F7 -> 1551.9063 | L9: ='03_Schedules'!G7 -> 1676.0588 | M9: ='03_Schedules'!H7 -> 1810.1435
B10: CDMO / Lozenges & APIs | C10: 265 | D10: 305 | E10: 356 | F10: 459 | G10: 477 | H10: 558 | I10: ='03_Schedules'!D9 -> 613.8 | J10: ='03_Schedules'!E9 -> 675.18 | K10: ='03_Schedules'!F9 -> 742.698 | L10: ='03_Schedules'!G9 -> 813.25431 | M10: ='03_Schedules'!H9 -> 886.4472
B11: Cost of Materials Consumed (COGS) | C11: 619 | D11: 711 | E11: 902 | F11: 1102 | G11: 1219 | H11: 1371 | I11: =I7*'03_Schedules'!C16 -> 1500.9327 | J11: =J7*'03_Schedules'!D16 -> 1652.4303 | K11: =K7*'03_Schedules'!E16 -> 1819.4041 | L11: =L7*'03_Schedules'!F16 -> 1977.1627 | M11: =M7*'03_Schedules'!G16 -> 2160.5084
B12: Gross Profit | C12: =C7-C11 -> 1156 | D12: =D7-D11 -> 1332 | E12: =E7-E11 -> 1522 | F12: =F7-F11 -> 2047 | G12: =G7-G11 -> 2265 | H12: =H7-H11 -> 2547 | I12: =I7-I11 -> 2812.0923 | J12: =J7-J11 -> 3095.9326 | ... M12: =M7-M11 -> 4101.8348
B13: Gross Margin % | C13: =C12/C7 -> 0.65126761 | D13: =D12/D7 -> 0.65198238 | E13: =E12/E7 -> 0.62788779 | F13: =F12/F7 -> 0.65004763 | G13: =G12/G7 -> 0.65011481 | H13: =H12/H7 -> 0.65007657 | I13: =I12/I7 -> 0.652 | J13: =J12/J7 -> 0.652 | ... M13: =M12/M7 -> 0.655
B14: Employee Benefit Expenses | C14: 338 | D14: 368 | E14: 451 | F14: 585 | G14: 632 | H14: 705 | I14: =I7*'03_Schedules'!C17 -> 776.3445 | J14: =J7*'03_Schedules'!D17 -> 845.20859 | K14: =K7*'03_Schedules'!E17 -> 914.93024 | L14: =L7*'03_Schedules'!F17 -> 991.44679 | M14: =M7*'03_Schedules'!G17 -> 1064.5983
B15: Other Operating Expenses | C15: 440 | D15: 404 | E15: 528 | F15: 766 | G15: 736 | H15: 810 | I15: =I7*'03_Schedules'!C18 -> 884.17013 | J15: =J7*'03_Schedules'!D18 -> 973.41439 | K15: =K7*'03_Schedules'!E18 -> 1071.7754 | L15: =L7*'03_Schedules'!F18 -> 1163.374 | M15: =M7*'03_Schedules'!G18 -> 1252.4686
B16: EBITDA (Operating Profit) | C16: =C12-C14-C15 -> 378 | D16: =D12-D14-D15 -> 560 | E16: =E12-E14-E15 -> 543 | F16: =F12-F14-F15 -> 696 | G16: =G12-G14-G15 -> 897 | H16: =H12-H14-H15 -> 1032 | I16: =I12-I14-I15 -> 1151.5777 | J16: =J12-J14-J15 -> 1277.3096 | ... M16: =M12-M14-M15 -> 1784.7678
B17: EBITDA Margin % | C17: =C16/C7 -> 0.21295775 | D17: =D16/D7 -> 0.27410671 | E17: =E16/E7 -> 0.2240099 | F17: =F16/F7 -> 0.22102255 | G17: =G16/G7 -> 0.25746269 | H17: =H16/H7 -> 0.26339969 | I17: =I16/I7 -> 0.267 | J17: =J16/J7 -> 0.269 | ... M17: =M16/M7 -> 0.285
B18: Depreciation & Amortization | C18: 66 | D18: 69 | E18: 73 | F18: 114 | G18: 138 | H18: 171 | I18: ='03_Schedules'!D39 -> 137.73213 | J18: ='03_Schedules'!E39 -> 139.58207 | K18: ='03_Schedules'!F39 -> 142.40333 | L18: ='03_Schedules'!G39 -> 145.0674 | M18: ='03_Schedules'!H39 -> 147.84958
B19: Operating Profit (EBIT) | C19: =C16-C18 -> 312 | D19: =D16-D18 -> 491 | E19: =E16-E18 -> 470 | F19: =F16-F18 -> 582 | G19: =G16-G18 -> 759 | H19: =H16-H18 -> 861 | I19: =I16-I18 -> 1013.8455 | J19: =J16-J18 -> 1137.7275 | ... M19: =M16-M18 -> 1636.9182
B20: Other Non-Operating Income | C20: 41 | D20: 112 | E20: 39 | F20: 10 | G20: 37 | H20: 38 | I20: 38 | J20: 38 | K20: 38 | L20: 38 | M20: 38
B21: Finance / Interest Costs | C21: 3 | D21: 7 | E21: 5 | F21: 36 | G21: 44 | H21: 12 | I21: ='03_Schedules'!D49 -> 1.19 | J21: ='03_Schedules'!E49 -> 0 | K21: ='03_Schedules'!F49 -> 0 | L21: ='03_Schedules'!G49 -> 0 | M21: ='03_Schedules'!H49 -> 0
B22: Profit Before Tax (PBT) | C22: =C19+C20-C21 -> 350 | D22: =D19+D20-D21 -> 596 | E22: =E19+E20-E21 -> 504 | F22: =F19+F20-F21 -> 556 | G22: =G19+G20-G21 -> 752 | H22: =H19+H20-H21 -> 887 | I22: =I19+I20-I21 -> 1050.6555 | J22: =J19+J20-J21 -> 1175.7275 | ... M22: =M19+M20-M21 -> 1674.9182
B23: Tax Expense | C23: 77 | D23: 148 | E23: 119 | F23: 145 | G23: 199 | H23: 227 | I23: =I22*25.2% -> 264.7652 | J23: =J22*25.2% -> 296.28334 | K23: =K22*25.2% -> 332.05024 | L23: =L22*25.2% -> 375.94758 | M23: =M22*25.2% -> 422.07939
B24: Effective Tax Rate % | C24: =C23/C22 -> 0.22 | D24: =D23/D22 -> 0.24832215 | E24: =E23/E22 -> 0.23611111 | F24: =F23/F22 -> 0.26079137 | G24: =G23/G22 -> 0.26462766 | H24: =H23/H22 -> 0.25591883 | I24: =I23/I22 -> 0.252 | J24: =J23/J22 -> 0.252 | ... M24: =M23/M22 -> 0.252
B25: Net Profit (PAT) | C25: =C22-C23 -> 273 | D25: =D22-D23 -> 448 | E25: =E22-E23 -> 385 | F25: =F22-F23 -> 411 | G25: =G22-G23 -> 553 | H25: =H22-H23 -> 660 | I25: =I22-I23 -> 785.89035 | J25: =J22-J23 -> 879.4442 | ... M25: =M22-M23 -> 1252.8388
B27: BALANCE SHEET
B29: Line Item | C29: FY20 | D29: FY21 | E29: FY22 | F29: FY23 | G29: FY24 | H29: FY25 | I29: FY26E | J29: FY27E | K29: FY28E | L29: FY29E | M29: FY30E
B30: EQUITY & LIABILITIES
B31: Equity Share Capital | C31: 15 | D31: 15 | E31: 15 | F31: 15 | G31: 16 | H31: 16 | I31: 16 | J31: 16 | K31: 16 | L31: 16 | M31: 16
B32: Reserves & Surplus | C32: 1420 | D32: 1794 | E32: 2119 | F32: 2465 | G32: 2908 | H32: 3418 | I32: =H32+I25 -> 4203.8903 | J32: =I32+J25 -> 5083.3345 | K32: =J32+K25 -> 6068.944 | L32: =K32+L25 -> 7184.8519 | M32: =L32+M25 -> 8437.6907
B33: Total Shareholders' Equity | C33: 1435 | D33: 1809 | E33: 2134 | F33: 2480 | G33: 2924 | H33: 3434 | I33: =SUM(I31:I32) -> 4219.8903 | J33: =SUM(J31:J32) -> 5099.3345 | K33: =SUM(K31:K32) -> 6084.944 | L33: =SUM(L31:L32) -> 7200.8519 | M33: =SUM(M31:M32) -> 8453.6907
B35: Total Borrowings / Debt | C35: 29 | D35: 45 | E35: 55 | F35: 572 | G35: 378 | H35: 28 | I35: ='03_Schedules'!D47 -> 0 | J35: ='03_Schedules'!E47 -> 0 | K35: ='03_Schedules'!F47 -> 0 | L35: ='03_Schedules'!G47 -> 0 | M35: ='03_Schedules'!H47 -> 0
B36: Trade Payables | C36: 245 | D36: 261 | E36: 285 | F36: 315 | G36: 372 | H36: 429 | I36: ='03_Schedules'!D29 -> 431.77516 | J36: ='03_Schedules'!E29 -> 475.35666 | K36: ='03_Schedules'!F29 -> 523.39023 | L36: ='03_Schedules'!G29 -> 541.6884 | M36: ='03_Schedules'!H29 -> 591.92011
B37: Other Current Liabilities & Provisions | C37: 104 | D37: 115 | E37: 127 | F37: 180 | G37: 315 | H37: 375 | I37: =I7*9.57% -> 412.75649 | J37: =J7*9.57% -> 454.41833 | K37: =K7*9.57% -> 500.33614 | L37: =L7*9.57% -> 548.44773 | M37: =M7*9.57% -> 599.30624
B38: TOTAL EQUITY & LIABILITIES | C38: 1813 | D38: =SUM(D33:D37) -> 2230 | E38: =SUM(E33:E37) -> 2601 | F38: =SUM(F33:F37) -> 3547 | G38: =SUM(G33:G37) -> 3989 | H38: =SUM(H33:H37) -> 4266 | I38: =I33+I36+I37 -> 5064.422 | J38: =J33+J36+J37 -> 6029.1095 | K38: =K33+K36+K37 -> 7108.6703 | L38: =L33+L36+L37 -> 8290.988 | M38: =M33+M36+M37 -> 9644.9171
B40: ASSETS
B41: Net PP&E / Fixed Assets | C41: 651 | D41: 634 | E41: 1277 | F41: 1901 | G41: 2004 | H41: 1968 | I41: ='03_Schedules'!D40 -> 1981.2237 | J41: ='03_Schedules'!E40 -> 2007.8344 | K41: ='03_Schedules'!F40 -> 2048.4171 | L41: ='03_Schedules'!G40 -> 2086.7387 | M41: ='03_Schedules'!H40 -> 2126.7594
B42: Trade Receivables | C42: 345 | D42: 392 | E42: 558 | F42: 578 | G42: 687 | H42: 815 | I42: ='03_Schedules'!D25 -> 850.78849 | J42: ='03_Schedules'!E25 -> 936.66336 | K42: ='03_Schedules'!F25 -> 1031.3108 | L42: ='03_Schedules'!G25 -> 1099.0779 | M42: ='03_Schedules'!H25 -> 1200.9973
B43: Inventory | C43: 328 | D43: 380 | E43: 460 | F43: 475 | G43: 518 | H43: 552 | I43: ='03_Schedules'!D27 -> 596.26094 | J43: ='03_Schedules'!E27 -> 656.44491 | K43: ='03_Schedules'!F27 -> 722.77698 | L43: ='03_Schedules'!G27 -> 758.36376 | M43: ='03_Schedules'!H27 -> 828.68815
B44: Other Current & Non-Current Assets | C44: 86 | D44: 146 | E44: 293 | F44: 384 | G44: 392 | H44: 172 | I44: 172 | J44: 172 | K44: 172 | L44: 172 | M44: 172
B45: Cash & Liquid Investments | C45: 403 | D45: 678 | E45: 13 | F45: 209 | G45: 388 | H45: 1110 | I45: =I63 -> 1502.3307 | J45: =J63 -> 1944.8815 | K45: =K63 -> 2431.9989 | L45: =L63 -> 3033.9617 | M45: =M63 -> 3686.2742
B46: TOTAL ASSETS | C46: 1813 | D46: =SUM(D41:D45) -> 2230 | E46: =SUM(E41:E45) -> 2601 | F46: =SUM(F41:F45) -> 3547 | G46: =SUM(G41:G45) -> 3989 | H46: 4266 | I46: =SUM(I41:I45) -> 5102.6039 | J46: =SUM(J41:J45) -> 5717.8241 | K46: =SUM(K41:K45) -> 6406.5038 | L46: =SUM(L41:L45) -> 7150.1421 | M46: =SUM(M41:M45) -> 8014.7191
...

Sheet 03_Schedules
A2: Schedule 1: Revenue Build & Segment Growth Assumptions
B4: Line Item | C4: FY25 | D4: FY26E | E4: FY27E | F4: FY28E | G4: FY29E | H4: FY30E
B5: Domestic Formulations (₹ Cr) | C5: 2145 | D5: =C5*(1+D6) -> 2380.95 | E5: =D5*(1+E6) -> 2642.8545 | F5: =E5*(1+F6) -> 2933.5685 | G5: =F5*(1+G6) -> 3241.5932 | H5: =G5*(1+H6) -> 3565.7525
B6: Domestic Growth Rate % | D6: 0.11 | E6: 0.11 | F6: 0.11 | G6: 0.105 | H6: 0.1
B7: International Formulations (₹ Cr) | C7: 1215 | D7: =C7*(1+D8) -> 1318.275 | E7: =D7*(1+E8) -> 1430.3284 | F7: =E7*(1+F8) -> 1551.9063 | G7: =F7*(1+G8) -> 1676.0588 | H7: =G7*(1+H8) -> 1810.1435
B8: International Growth Rate % | D8: 0.085 | E8: 0.085 | F8: 0.085 | G8: 0.08 | H8: 0.08
B9: CDMO / Lozenges & APIs (₹ Cr) | C9: 558 | D9: =C9*(1+D10) -> 613.8 | E9: =D9*(1+E10) -> 675.18 | F9: =E9*(1+F10) -> 742.698 | G9: =F9*(1+G10) -> 813.25431 | H9: =G9*(1+H10) -> 886.4472
B10: CDMO Growth Rate % | D10: 0.1 | E10: 0.1 | F10: 0.1 | G10: 0.095 | H10: 0.09
B11: Total Revenue (₹ Cr) | C11: 3918 | D11: =D5+D7+D9 -> 4313.025 | E11: =E5+E7+E9 -> 4748.3629 | F11: =F5+F7+F9 -> 5228.1728 | G11: =G5+G7+G9 -> 5730.9063 | H11: =H5+H7+H9 -> 6262.3432
A13: Schedule 2: Cost Structure % Drivers
B15: Line Item | C15: FY26E | D15: FY27E | E15: FY28E | F15: FY29E | G15: FY30E
B16: COGS % of Revenue | C16: 0.348 | D16: 0.348 | E16: 0.348 | F16: 0.345 | G16: 0.345
B17: Employee Expenses % of Revenue | C17: 0.18 | D17: 0.178 | E17: 0.175 | F17: 0.173 | G17: 0.17
B18: Other OpEx % of Revenue | C18: 0.205 | D18: 0.205 | E18: 0.205 | F18: 0.203 | G18: 0.2
B19: Calculated EBITDA Margin % | C19: 0.267 | D19: =1-(D16+D17+D18) -> 0.269 | E19: =1-(E16+E17+E18) -> 0.272 | F19: =1-(F16+F17+F18) -> 0.279 | G19: =1-(G16+G17+G18) -> 0.285
A21: Schedule 3: Working Capital Schedule
B23: Line Item | C23: FY25 | D23: FY26E | E23: FY27E | F23: FY28E | G23: FY29E | H23: FY30E
B24: Debtor Days (DSO) | C24: 76 | D24: 72 | E24: 72 | F24: 72 | G24: 70 | H24: 70
B25: Trade Receivables (₹ Cr) | C25: 815 | D25: =(D24*D11)/365 -> 850.78849 | E25: =(E24*E11)/365 -> 936.66336 | F25: =(F24*F11)/365 -> 1031.3108 | G25: =(G24*G11)/365 -> 1099.0779 | H25: =(H24*H11)/365 -> 1200.9973
B26: Inventory Days (DIO) | C26: 147 | D26: 145 | E26: 145 | F26: 145 | G26: 140 | H26: 140
B27: Inventory (₹ Cr) | C27: 552 | D27: =(D26*'02_3_Statement_Model'!I11)/365 -> 596.26094 | E27: =(E26*'02_3_Statement_Model'!J11)/365 -> 656.44491 | F27: =(F26*'02_3_Statement_Model'!K11)/365 -> 722.77698 | G27: =(G26*'02_3_Statement_Model'!L11)/365 -> 758.36376 | H27: =(H26*'02_3_Statement_Model'!M11)/365 -> 828.68815
B28: Payable Days (DPO) | C28: 114 | D28: 105 | E28: 105 | F28: 105 | G28: 100 | H28: 100
B29: Trade Payables (₹ Cr) | C29: 429 | D29: =(D28*'02_3_Statement_Model'!I11)/365 -> 431.77516 | E29: =(E28*'02_3_Statement_Model'!J11)/365 -> 475.35666 | F29: =(F28*'02_3_Statement_Model'!K11)/365 -> 523.39023 | G29: =(G28*'02_3_Statement_Model'!L11)/365 -> 541.6884 | H29: =(H28*'02_3_Statement_Model'!M11)/365 -> 591.92011
B30: Net Working Capital (NWC) | C30: 938 | D30: =D25+D27-D29 -> 1015.2743 | E30: =E25+E27-E29 -> 1117.7516 | F30: =F25+F27-F29 -> 1230.6975 | G30: =G25+G27-G29 -> 1315.7533 | H30: =H25+H27-H29 -> 1437.7654
B31: Δ Change in NWC (₹ Cr) | D31: =D30-C30 -> 77.274268 | E31: =E30-D30 -> 102.47734 | F31: =F30-E30 -> 112.94594 | G31: =G30-F30 -> 85.05573 | H31: =H30-G30 -> 122.01209
A33: Schedule 4: PP&E / CapEx & Depreciation Roll-Forward Schedule
B35: Line Item | C35: FY25 | D35: FY26E | E35: FY27E | F35: FY28E | G35: FY29E | H35: FY30E
B36: Beginning Net PP&E (₹ Cr) | C36: 2004 | D36: 1968 | E36: =D40 -> 1981.2237 | F36: =E40 -> 2007.8344 | G36: =F40 -> 2048.4171 | H36: =G40 -> 2086.7387
B37: CapEx % of Revenue | D37: 0.035 | E37: 0.035 | F37: 0.035 | G37: 0.032 | H37: 0.03
B38: CapEx Addition (₹ Cr) | C38: 135 | D38: =D11*D37 -> 150.95588 | E38: =E11*E37 -> 166.1927 | F38: =F11*F37 -> 182.98605 | G38: =G11*G37 -> 183.389 | H38: =H11*H37 -> 187.8703
B39: Depreciation Expense (₹ Cr) | C39: 171 | D39: =(D36+D38)*6.5% -> 137.73213 | E39: =(E36+E38)*6.5% -> 139.58207 | F39: =(F36+F38)*6.5% -> 142.40333 | G39: =(G36+G38)*6.5% -> 145.0674 | H39: =(H36+H38)*6.5% -> 147.84958
B40: Ending Net PP&E (₹ Cr) | C40: 1968 | D40: =D36+D38-D39 -> 1981.2237 | E40: =E36+E38-E39 -> 2007.8344 | F40: =F36+F38-F39 -> 2048.4171 | G40: =G36+G38-G39 -> 2086.7387 | H40: =H36+H38-H39 -> 2126.7594
A42: Schedule 5: Debt & Interest Schedule
B44: Line Item | C44: FY25 | D44: FY26E | E44: FY27E | F44: FY28E | G44: FY29E | H44: FY30E
B45: Beginning Total Debt (₹ Cr) | C45: 378 | D45: 28 | E45: 0 | F45: 0 | G45: 0 | H45: 0
B46: Debt Principal Repayment (₹ Cr) | C46: 350 | D46: 28 | E46: 0 | F46: 0 | G46: 0 | H46: 0
B47: Ending Total Debt (₹ Cr) | C47: 28 | D47: 0 | E47: 0 | F47: 0 | G47: 0 | H47: 0
B48: Interest Rate % | D48: 0.085 | E48: 0.085 | F48: 0.085 | G48: 0.085 | H48: 0.085
B49: Interest Expense (₹ Cr) | C49: 12 | D49: =(D45+D47)/2 * 8.5% -> 1.19 | E49: =(E45+E47)/2 * 8.5% -> 0 | F49: =(F45+F47)/2 * 8.5% -> 0 | G49: =(G45+G47)/2 * 8.5% -> 0 | H49: =(H45+H47)/2 * 8.5% -> 0

Sheet 04_DCF_Valuation
A2: Unlevered Free Cash Flow (UFCF) Build
B4: Line Item (Column B) | C4: FY26E | D4: FY27E | E4: FY28E | F4: FY29E | G4: FY30E
B5: Operating Profit (EBIT) | C5: 1013.85 | D5: 1137.73 | E5: 1279.66 | F5: 1453.86 | G5: 1636.92
B6: Less: Tax on EBIT (25.2%) | C6: 255.49 | D6: =D5*25.2% -> 286.70796 | E6: =E5*25.2% -> 322.47432 | F6: =F5*25.2% -> 366.37272 | G6: =G5*25.2% -> 412.50384
B7: NOPAT (EBIT × 1-t) | C7: 758.36 | D7: =D5-D6 -> 851.02204 | E7: =E5-E6 -> 957.18568 | F7: =F5-F6 -> 1087.4873 | G7: =G5-G6 -> 1224.4162
B8: Add: Depreciation & Amortization | C8: 137.73 | D8: ='03_Schedules'!E39 -> 139.58207 | E8: ='03_Schedules'!F39 -> 142.40333 | F8: ='03_Schedules'!G39 -> 145.0674 | G8: ='03_Schedules'!H39 -> 147.84958
B9: Less: CapEx Additions | C9: 150.96 | D9: ='03_Schedules'!E38 -> 166.1927 | E9: ='03_Schedules'!F38 -> 182.98605 | F9: ='03_Schedules'!G38 -> 183.389 | G9: ='03_Schedules'!H38 -> 187.8703
B10: Less: ΔΔ Change in NWC | C10: 77.27 | D10: ='03_Schedules'!E31 -> 102.47734 | E10: ='03_Schedules'!F31 -> 112.94594 | F10: ='03_Schedules'!G31 -> 85.05573 | G10: ='03_Schedules'!H31 -> 122.01209
B11: Unlevered Free Cash Flow (UFCF) | C11: 667.86 | D11: =D7+D8-D9-D10 -> 721.93407 | E11: =E7+E8-E9-E10 -> 803.65702 | F11: =F7+F8-F9-F10 -> 964.10995 | G11: =G7+G8-G9-G10 -> 1062.3834
A13: WACC Table
B15: Line Item | C15: Value
B16: Risk-Free Rate (RfRf​) | C16: 0.07
B17: Beta (ββ) | C17: 0.8
B18: Equity Risk Premium (ERP) | C18: 0.065
B19: Cost of Equity (KeKe​) | C19: =C16+C17*C18 -> 0.122
B20: Pre-Tax Cost of Debt (KdKd​) | C20: 0.085
B21: Tax Rate | C21: 0.252
B22: After-Tax Cost of Debt | C22: =C20*(1-C21) -> 0.06358
B23: Weight of Equity (WeWe​) | C23: 0.95
B24: Weight of Debt (WdWd​) | C24: 0.05
B25: Weighted Average Cost of Capital (WACC) | C25: =C19*C23+C22*C24 -> 0.119079
A27: Terminal Value & Implied Share Price
B29: Line Item | C29: Formula / Value
B30: Terminal Growth Rate (gg) | C30: 0.05 | E30: =C39 -> 852.60236 | F30: 0.04 | G30: 0.045 | H30: 0.05 | I30: 0.055 | J30: 0.06 | K30: (Terminal Growth Rate →)
B31: FY30E Terminal Value (TV) | C31: =G11*(1+C30)/(C25-C30) -> 16148.215 | E31: 0.105 | F31: 931.96169 | G31: 990.7494 | H31: 1060.2258 | I31: 1143.5974 | J31: 1245.4961
B32: PV of 5-Year UFCFs (FY26E–FY30E) | C32: =NPV(C25,C11:G11) -> 2966.7425 | E32: 0.112 | F32: 845.01102 | G32: 891.35292 | H32: 945.16931 | I32: 1008.4272 | J32: 1083.85
B33: PV of Terminal Value | C33: =C31/(1+C25)^5 -> 9200.6982 | E33: 0.119 | F33: 773.54055 | G33: 810.83302 | H33: 853.53019 | I33: 902.89879 | J33: 960.63495 | K33: (WACC ↓)
B34: Enterprise Value (EV) | C34: =C32+C33 -> 12167.441 | E34: 0.126 | F34: 713.76814 | G34: 744.29367 | H34: 778.83572 | I34: 818.24284 | J34: 863.62075
B35: Add: Cash & Liquid Investments | C35: 1110 | E35: 0.133 | F35: 663.05043 | G35: 688.39675 | H35: 716.79685 | I35: 748.83799 | J35: 785.26832
B36: Less: Total Debt | C36: 28
B37: Implied Equity Value | C37: =C34+C35-C36 -> 13249.441
B38: Shares Outstanding (Post-Split) | C38: 15.54
B39: Implied Standalone Share Price | C39: =C37/C38 -> 852.60236

Sheet 05_LBO_Returns
A1: J.B. CHEMICALS & PHARMACEUTICALS — KKR LBO & TORRENT EXIT RETURNS MODEL
B4: Line Item | C4: Value
B5: 2020 KKR Entry Share Price | C5: 745
B6: Shares Acquired (Promoter + Open Offer) | C6: 5.03
B7: Total KKR Entry Outlay | C7: 3747.35
B8: Debt Financing Raised (HoldCo/NCDs) | C8: 1000
B9: KKR Sponsor Equity Check | C9: 2747.35
B11: 2025 Torrent Exit Share Price | C11: 1600
B12: Shares Sold at Exit (Post 1:2 Split) | C12: 10.06
B13: Gross Exit Equity Proceeds | C13: 16096
B14: KKR Holding Period (Years) | C14: 4.5
B17: Uses of Funds (Where Money Went) (₹ Cr) | C17: ₹ Cr | D17: Sources of Funds (How Paid For) (₹ Cr) | E17: ₹ Cr
B18: Equity Purchase Price (53.8% Stake) | C18: 3747.35 | D18: KKR Sponsor Equity Check | E18: 2747.35
B19: Advisory & Financing Fees | C19: 50 | D19: HoldCo Debt / Private Credit | E19: 1050
B20: Total Uses of Funds | C20: =SUM(C18:C19) -> 3797.35 | D20: Total Sources of Funds | E20: =SUM(E18:E19) -> 3797.35
B24: Date / Year | C24: Deal Event | D24: KKR Cash Flow (₹ Cr)
B25: July 2020 (Day 0) | C25: KKR Initial Equity Check Outflow | D25: =-C9 -> -2747.35
B26: FY21 (Year 1) | C26: Dividend Cash Collected | D26: 32
B27: FY22 (Year 2) | C27: Dividend Cash Collected | D27: 42
B28: FY23 (Year 3) | C28: Dividend Cash Collected | D28: 52
B29: FY24 (Year 4) | C29: Dividend Cash Collected | D29: 70
B30: Early 2025 (Exit) | C30: Gross Torrent Exit Proceeds | D30: =C13 -> 16096
B34: Line Item | C34: Formula
B35: Total Cash Returned to KKR (₹ Cr) | C35: =SUM(D26:D30) -> 16292
B36: Net Profit Realized (₹ Cr) | C36: =C35+D25 -> 13544.65
B37: Multiple on Invested Capital (MoIC) | C37: =C35/(-D25) -> 5.9300781
B38: Gross Internal Rate of Return (IRR) | C38: =(C37^(1/C14))-1 -> 0.48522141
B42: Value Creation Driver | C42: Value / Formula | D42: % Contribution
B43: EBITDA Expansion Gain (₹ Cr) | C43: 4753.35 | D43: =C43/$C$46 -> 0.3509393
B44: Multiple Expansion Gain (₹ Cr) | C44: 7791.3 | D44: =C44/$C$46 -> 0.57523081
B45: Deleveraging / Cash Sweep (₹ Cr) | C45: 1000 | D45: =C45/$C$46 -> 0.073829889
B46: Total Equity Value Created | C46: 13544.65 | D46: =C46/$C$46 -> 1
